torch.Size([7631, 27])
torch.Size([7631])
INFO flwr 2024-02-13 14:25:03,457 | grpc.py:52 | Opened insecure gRPC connection (no certificates were passed)
DEBUG flwr 2024-02-13 14:25:03,463 | connection.py:42 | ChannelConnectivity.IDLE
DEBUG flwr 2024-02-13 14:25:03,464 | connection.py:42 | ChannelConnectivity.CONNECTING
DEBUG flwr 2024-02-13 14:25:03,471 | connection.py:42 | ChannelConnectivity.TRANSIENT_FAILURE
DEBUG flwr 2024-02-13 14:25:03,671 | connection.py:141 | gRPC channel closed
Traceback (most recent call last):
  File "/Users/yunbo/Documents/GitHub/PFL_Optimiozation/Model_training/client_MLP0.py", line 338, in <module>
    fl.client.start_numpy_client(
  File "/Users/yunbo/anaconda3/envs/basic/lib/python3.9/site-packages/flwr/client/app.py", line 401, in start_numpy_client
    start_client(
  File "/Users/yunbo/anaconda3/envs/basic/lib/python3.9/site-packages/flwr/client/app.py", line 275, in start_client
    task_ins = receive()
  File "/Users/yunbo/anaconda3/envs/basic/lib/python3.9/site-packages/flwr/client/grpc_client/connection.py", line 118, in receive
    server_message = next(server_message_iterator)
  File "/Users/yunbo/anaconda3/envs/basic/lib/python3.9/site-packages/grpc/_channel.py", line 540, in __next__
    return self._next()
  File "/Users/yunbo/anaconda3/envs/basic/lib/python3.9/site-packages/grpc/_channel.py", line 966, in _next
    raise self
grpc._channel._MultiThreadedRendezvous: <_MultiThreadedRendezvous of RPC that terminated with:
	status = StatusCode.UNAVAILABLE
	details = "failed to connect to all addresses; last error: UNKNOWN: ipv4:127.0.0.1:8094: Failed to connect to remote host: Connection refused"
	debug_error_string = "UNKNOWN:Error received from peer  {grpc_message:"failed to connect to all addresses; last error: UNKNOWN: ipv4:127.0.0.1:8094: Failed to connect to remote host: Connection refused", grpc_status:14, created_time:"2024-02-13T14:25:03.465118+00:00"}"
>
Traceback (most recent call last):
  File "/Users/yunbo/Documents/GitHub/PFL_Optimiozation/Model_training/client_MLP0.py", line 338, in <module>
    fl.client.start_numpy_client(
  File "/Users/yunbo/anaconda3/envs/basic/lib/python3.9/site-packages/flwr/client/app.py", line 401, in start_numpy_client
    start_client(
  File "/Users/yunbo/anaconda3/envs/basic/lib/python3.9/site-packages/flwr/client/app.py", line 275, in start_client
    task_ins = receive()
  File "/Users/yunbo/anaconda3/envs/basic/lib/python3.9/site-packages/flwr/client/grpc_client/connection.py", line 118, in receive
    server_message = next(server_message_iterator)
  File "/Users/yunbo/anaconda3/envs/basic/lib/python3.9/site-packages/grpc/_channel.py", line 540, in __next__
    return self._next()
  File "/Users/yunbo/anaconda3/envs/basic/lib/python3.9/site-packages/grpc/_channel.py", line 966, in _next
    raise self
grpc._channel._MultiThreadedRendezvous: <_MultiThreadedRendezvous of RPC that terminated with:
	status = StatusCode.UNAVAILABLE
	details = "failed to connect to all addresses; last error: UNKNOWN: ipv4:127.0.0.1:8094: Failed to connect to remote host: Connection refused"
	debug_error_string = "UNKNOWN:Error received from peer  {grpc_message:"failed to connect to all addresses; last error: UNKNOWN: ipv4:127.0.0.1:8094: Failed to connect to remote host: Connection refused", grpc_status:14, created_time:"2024-02-13T14:25:03.465118+00:00"}"
>