torch.Size([9133, 27])
torch.Size([9133])
INFO flwr 2024-02-12 14:27:22,041 | grpc.py:52 | Opened insecure gRPC connection (no certificates were passed)
DEBUG flwr 2024-02-12 14:27:22,042 | connection.py:42 | ChannelConnectivity.IDLE
DEBUG flwr 2024-02-12 14:27:22,048 | connection.py:42 | ChannelConnectivity.CONNECTING
DEBUG flwr 2024-02-12 14:27:22,049 | connection.py:42 | ChannelConnectivity.TRANSIENT_FAILURE
DEBUG flwr 2024-02-12 14:27:22,252 | connection.py:141 | gRPC channel closed
Traceback (most recent call last):
  File "/Users/yunbo/Documents/GitHub/PFL_Optimiozation/Model_training/client_CNN0_MLP.py", line 401, in <module>
    fl.client.start_numpy_client(
  File "/Users/yunbo/anaconda3/envs/basic/lib/python3.9/site-packages/flwr/client/app.py", line 401, in start_numpy_client
    start_client(
  File "/Users/yunbo/anaconda3/envs/basic/lib/python3.9/site-packages/flwr/client/app.py", line 275, in start_client
    task_ins = receive()
  File "/Users/yunbo/anaconda3/envs/basic/lib/python3.9/site-packages/flwr/client/grpc_client/connection.py", line 118, in receive
    server_message = next(server_message_iterator)
  File "/Users/yunbo/anaconda3/envs/basic/lib/python3.9/site-packages/grpc/_channel.py", line 540, in __next__
    return self._next()
  File "/Users/yunbo/anaconda3/envs/basic/lib/python3.9/site-packages/grpc/_channel.py", line 966, in _next
    raise self
grpc._channel._MultiThreadedRendezvous: <_MultiThreadedRendezvous of RPC that terminated with:
	status = StatusCode.UNAVAILABLE
	details = "failed to connect to all addresses; last error: UNKNOWN: ipv4:127.0.0.1:8090: Failed to connect to remote host: Connection refused"
	debug_error_string = "UNKNOWN:Error received from peer  {created_time:"2024-02-12T14:27:22.049826+00:00", grpc_status:14, grpc_message:"failed to connect to all addresses; last error: UNKNOWN: ipv4:127.0.0.1:8090: Failed to connect to remote host: Connection refused"}"
>
Traceback (most recent call last):
  File "/Users/yunbo/Documents/GitHub/PFL_Optimiozation/Model_training/client_CNN0_MLP.py", line 401, in <module>
    fl.client.start_numpy_client(
  File "/Users/yunbo/anaconda3/envs/basic/lib/python3.9/site-packages/flwr/client/app.py", line 401, in start_numpy_client
    start_client(
  File "/Users/yunbo/anaconda3/envs/basic/lib/python3.9/site-packages/flwr/client/app.py", line 275, in start_client
    task_ins = receive()
  File "/Users/yunbo/anaconda3/envs/basic/lib/python3.9/site-packages/flwr/client/grpc_client/connection.py", line 118, in receive
    server_message = next(server_message_iterator)
  File "/Users/yunbo/anaconda3/envs/basic/lib/python3.9/site-packages/grpc/_channel.py", line 540, in __next__
    return self._next()
  File "/Users/yunbo/anaconda3/envs/basic/lib/python3.9/site-packages/grpc/_channel.py", line 966, in _next
    raise self
grpc._channel._MultiThreadedRendezvous: <_MultiThreadedRendezvous of RPC that terminated with:
	status = StatusCode.UNAVAILABLE
	details = "failed to connect to all addresses; last error: UNKNOWN: ipv4:127.0.0.1:8090: Failed to connect to remote host: Connection refused"
	debug_error_string = "UNKNOWN:Error received from peer  {created_time:"2024-02-12T14:27:22.049826+00:00", grpc_status:14, grpc_message:"failed to connect to all addresses; last error: UNKNOWN: ipv4:127.0.0.1:8090: Failed to connect to remote host: Connection refused"}"
>