Traceback (most recent call last):
  File "/Users/yunbo/Documents/GitHub/PFL_Optimiozation/Model_training/client_test.py", line 94, in <module>
    dataset = file[sheet_name][:]
  File "h5py/_objects.pyx", line 54, in h5py._objects.with_phil.wrapper
  File "h5py/_objects.pyx", line 55, in h5py._objects.with_phil.wrapper
  File "/Users/yunbo/anaconda3/envs/basic/lib/python3.9/site-packages/h5py/_hl/group.py", line 357, in __getitem__
    oid = h5o.open(self.id, self._e(name), lapl=self._lapl)
  File "h5py/_objects.pyx", line 54, in h5py._objects.with_phil.wrapper
  File "h5py/_objects.pyx", line 55, in h5py._objects.with_phil.wrapper
  File "h5py/h5o.pyx", line 189, in h5py.h5o.open
KeyError: "Unable to open object (object 'Southeast Asia' doesn't exist)"
Traceback (most recent call last):
  File "/Users/yunbo/Documents/GitHub/PFL_Optimiozation/Model_training/client_test.py", line 94, in <module>
    dataset = file[sheet_name][:]
  File "h5py/_objects.pyx", line 54, in h5py._objects.with_phil.wrapper
  File "h5py/_objects.pyx", line 55, in h5py._objects.with_phil.wrapper
  File "/Users/yunbo/anaconda3/envs/basic/lib/python3.9/site-packages/h5py/_hl/group.py", line 357, in __getitem__
    oid = h5o.open(self.id, self._e(name), lapl=self._lapl)
  File "h5py/_objects.pyx", line 54, in h5py._objects.with_phil.wrapper
  File "h5py/_objects.pyx", line 55, in h5py._objects.with_phil.wrapper
  File "h5py/h5o.pyx", line 189, in h5py.h5o.open
KeyError: "Unable to open object (object 'Southeast Asia' doesn't exist)"